const asyncHandler = (requestHandler) => {
  return (req, res, next) => {
    Promise.resolve(requestHandler(req, res, next)).catch((err) => next(err));
  };
};

export { asyncHandler };

//Below is the try catch way of handling the situation

// const asyncHandler = (fn) => async (req, res, next) => {
//   try {
//     await fn(req, res, next);
//   } catch (error) {
//     res.status(error.code || 500).json({
//       success: false,
//       message: error.message,
//     });
//   }
// };
